<mujoco model="reacher">
    <custom>
        <numeric name="ndims" size="1" data="3"/>
        <numeric name="njoints" size="1" data="4"/>
    </custom>    

	<compiler angle="radian" inertiafromgeom="true"/>
    
    <default>
		<joint armature="1" damping="1" limited="true"/>
		<geom contype="0" friction="1 0.1 0.1" rgba="0.7 0.7 0 1"/>
	</default>
    
    <option gravity="0 0 -9.81" integrator="RK4" timestep="0.01"/>
    
    <worldbody>
		<!-- Arena -->
		<geom conaffinity="0" contype="0" name="ground" pos="0 0 0" rgba="0.9 0.9 0.9 1" size="1 1 10" type="plane"/>

		<!-- Arm -->
		<geom conaffinity="0" contype="0" fromto="0 0 0 0 0 0.02" name="root" rgba="0.9 0.4 0.6 1" size=".011" type="cylinder"/>
		<body name="base" pos="0 0 .01">
			<geom fromto="0 0 0 0 0 0.1" name="link0" rgba="0.0 0.4 0.6 1" size=".01" type="capsule"/>
			<joint axis="0 0 1" limited="true" range="-3.0 3.0" name="j0" pos="0 0 0" type="hinge"/>
            
            <body name="j0" pos="0 0 0.1">
				<geom fromto="0 0 0 0 0 0.1" name="link1" rgba="0.0 0.4 0.6 1" size=".01" type="capsule"/>
                <joint axis="1 0 0" limited="true" range="-3.0 3.0" name="j1" pos="0 0 0" type="hinge"/>
                
                <body name="j1" pos="0 0 0.1">
                    <geom fromto="0 0 0 0 0 0.1" name="link2" rgba="0.0 0.4 0.6 1" size=".01" type="capsule"/>
                    <joint axis="0 0 1" limited="true" range="-3.0 3.0" name="j2" pos="0 0 0" type="hinge"/>    
                    
                    <body name="j2" pos="0 0 0.1">
                        <geom fromto="0 0 0 0 0 0.1" name="link3" rgba="0.0 0.4 0.6 1" size=".01" type="capsule"/>
                        <joint axis="1 0 0" limited="true" range="-3.0 3.0" name="j3" pos="0 0 0" type="hinge"/>    
                        
                        <body name="j3" pos="0 0 0.11">
                            <geom contype="0" name="fingertip" pos="0 0 0" rgba="0.0 0.8 0.6 1" size=".01" type="sphere"/>
                        </body>
                    </body>
                </body>
			</body>
        </body>

		<!-- Target -->
		<body name="target" pos=".1 -.1 .01" gravcomp="1">
			<joint armature="0" axis="1 0 0" damping="0" limited="false" name="target_x" pos="0 0 0" type="slide"/>
			<joint armature="0" axis="0 1 0" damping="0" limited="false" name="target_y" pos="0 0 0" type="slide"/>
			<joint armature="0" axis="0 0 1" damping="0" limited="false" name="target_z" pos="0 0 0" type="slide"/>
			<geom conaffinity="0" contype="0" name="target" pos="0 0 0" rgba="0.9 0.2 0.2 1" size=".009" type="sphere"/>
		</body>
	</worldbody>
    
    <actuator>
		<motor ctrllimited="true" ctrlrange="-1.0 1.0" gear="200.0" joint="j0"/>
		<motor ctrllimited="true" ctrlrange="-1.0 1.0" gear="200.0" joint="j1"/>
		<motor ctrllimited="true" ctrlrange="-1.0 1.0" gear="200.0" joint="j2"/>
		<motor ctrllimited="true" ctrlrange="-1.0 1.0" gear="200.0" joint="j3"/>
	</actuator>
</mujoco>
